<?xml version="1.0"?>
<robot name="realsense_stand" xmlns:xacro="http://ros.org/wiki/xacro">
  <xacro:macro name="sensor_realsense_stand" params="parent x y z roll pitch yaw">


    <link name="realsense_base_spacer">
      <visual>
	<geometry>
	  <cylinder length="0.05" radius="0.05"/>
	</geometry>
      </visual>
      <inertial>
	<origin xyz="0 0 0" rpy="0 0 0"/>
	<mass value="0.01"/>
	<inertia ixx="0.001" ixy="0.0" ixz="0.0" iyy="0.001" iyz="0.0" izz="0.001"/>
      </inertial>
    </link>
    
    <link name="realsense_base_stand">
      <visual>
	<geometry>
	  <mesh filename="file://$(find turtlebot_description)/meshes/stand/base.dae"></mesh>
	</geometry>
      </visual>
      <inertial>
	<origin xyz="0 0 0" rpy="0 0 0"/>
	<mass value="0.01"/>
	<inertia ixx="0.001" ixy="0.0" ixz="0.0" iyy="0.001" iyz="0.0" izz="0.001"/>
      </inertial>
    </link>
    
    <link name="realsense_fork_stand">
      <visual>
	<geometry>
	  <mesh filename="file://$(find turtlebot_description)/meshes/stand/fork.dae"></mesh>
	</geometry>
      </visual>
      <inertial>
	<origin xyz="0 0 0" rpy="0 0 0"/>
	<mass value="0.01"/>
	<inertia ixx="0.001" ixy="0.0" ixz="0.0" iyy="0.001" iyz="0.0" izz="0.001"/>
      </inertial>
    </link>
    
    <link name="realsense_plate_stand">
      <visual>
	<geometry>
	  <mesh filename="file://$(find turtlebot_description)/meshes/stand/plate.dae"></mesh>
	</geometry>
      </visual>
      <inertial>
	<origin xyz="0 0 0" rpy="0 0 0"/>
	<mass value="0.01"/>
	<inertia ixx="0.001" ixy="0.0" ixz="0.0" iyy="0.001" iyz="0.0" izz="0.001"/>
      </inertial>
    </link>   
    
    <link name="realsense_screen_stand">
      <visual>
	<geometry>
	  <mesh filename="file://$(find turtlebot_description)/meshes/stand/screen.dae"></mesh>
	</geometry>
      </visual>
      <inertial>
	<origin xyz="0 0 0" rpy="0 0 0"/>
	<mass value="0.01"/>
	<inertia ixx="0.001" ixy="0.0" ixz="0.0" iyy="0.001" iyz="0.0" izz="0.001"/>
      </inertial>
    </link>   
    


    <joint name="parent_base_spacer_joint" type="fixed">
      <parent link="${parent}"/>
      <child link="realsense_base_spacer"/>
      <origin xyz="${x} ${y} ${z}" rpy="${roll} ${pitch} ${yaw}"/>
      <axis xyz="0 1 0" />
    </joint>



    
    <joint name="base_socaer_base_joint" type="fixed">
      <parent link="realsense_base_spacer"/>
      <child link="realsense_base_stand"/>
      <origin xyz="0 0 0.025" rpy="0 0 0"/>
      <axis xyz="0 1 0" />
    </joint>
    
    <joint name="base_fork_joint" type="continuous">
      <parent link="realsense_base_stand"/>
      <child link="realsense_fork_stand"/>
      <origin xyz="0 0 0" rpy="0 0 0"/>
      <axis xyz="0 0 1" />
      <limit effort="750000.0" velocity="30.0"/>
    </joint>
    <joint name="fork_plate_joint" type="continuous">
      <parent link="realsense_fork_stand"/>
      <child link="realsense_plate_stand"/>
      <origin xyz="0 0 0.197" rpy="0 0 0"/>
      <axis xyz="0 1 0" />
      <limit effort="750000.0" velocity="30.0"/>
    </joint>
    <joint name="plate_screen_joint" type="fixed">
      <parent link="realsense_plate_stand"/>
      <child link="realsense_screen_stand"/>
      <origin xyz="0 0 -0.197" rpy="0 0 0"/>
      <axis xyz="0 1 0" />
    </joint>
    
    <transmission name="base_fork_joint_transmission">
	<type>transmission_interface/SimpleTransmission</type>
	<joint name="base_fork_joint">
	    <hardwareInterface>VelocityJointInterface</hardwareInterface>
	    <mechanicalReduction>1</mechanicalReduction>
	</joint>
	<actuator name="base_fork_joint_actuator">
	    <hardwareInterface>VelocityJointInterface</hardwareInterface>
	    <mechanicalReduction>1</mechanicalReduction>
	</actuator>
    </transmission>
    
    <transmission name="fork_plate_joint_transmission">
	<type>transmission_interface/SimpleTransmission</type>
	<joint name="fork_plate_joint">
	    <hardwareInterface>VelocityJointInterface</hardwareInterface>
	    <mechanicalReduction>1</mechanicalReduction>
	</joint>
	<actuator name="fork_plate_joint_actuator">
	    <hardwareInterface>VelocityJointInterface</hardwareInterface>
	    <mechanicalReduction>1</mechanicalReduction>
	</actuator>
    </transmission>

    <gazebo reference="realsense_base_stand">
      <material>Gazebo/Grey</material>
    </gazebo>
    <gazebo reference="realsense_fork_stand">
      <material>Gazebo/Grey</material>
    </gazebo>
    <gazebo reference="realsense_plate_stand">
      <material>Gazebo/Grey</material>
    </gazebo>
    <gazebo reference="realsense_screen_stand">
      <material>Gazebo/Grey</material>
    </gazebo>
    
    <gazebo>    
    <plugin name="gazebo_ros_control" filename="libgazebo_ros_control.so"/>
    </gazebo>
    
    
  </xacro:macro>
</robot>